Time slot   0
ld_routine
Time slot   1
	Loaded a process at input/proc/p0s, PID: 1 PRIO: 130
	CPU 2: Dispatched process  1
Time slot   2
	Loaded a process at input/proc/s3, PID: 2 PRIO: 39
	CPU 3: Dispatched process  2
Time slot   3
	CPU 2: Put process  1 to run queue
Time slot   4
	Loaded a process at input/proc/m1s, PID: 3 PRIO: 15
	CPU 3: Put process  2 to run queue
	CPU 2: Dispatched process  3
	CPU 0: Dispatched process  1
Time slot   5
Time slot   6
	Loaded a process at input/proc/s2, PID: 4 PRIO: 120
	CPU 0: Put process  1 to run queue
	CPU 2: Put process  3 to run queue
	CPU 1: Dispatched process  4
Time slot   7
	Loaded a process at input/proc/m0s, PID: 5 PRIO: 120
	CPU 2: Dispatched process  5
	CPU 0: Dispatched process  1
Time slot   8
	CPU 1: Put process  4 to run queue
Time slot   9
	Loaded a process at input/proc/p1s, PID: 6 PRIO: 15
	CPU 1: Dispatched process  3
	CPU 0: Put process  1 to run queue
	CPU 0: Dispatched process  2
	CPU 2: Put process  5 to run queue
	CPU 2: Dispatched process  5
	CPU 3: Dispatched process  6
Time slot  10
Time slot  11
	Loaded a process at input/proc/s0, PID: 7 PRIO: 38
	CPU 2: Put process  5 to run queue
	CPU 2: Dispatched process  7
	CPU 3: Put process  6 to run queue
	CPU 3: Dispatched process  5
	CPU 0: Put process  2 to run queue
	CPU 0: Dispatched process  4
	CPU 1: Put process  3 to run queue
	CPU 1: Dispatched process  1
Time slot  12
Time slot  13
	CPU 0: Put process  4 to run queue
	CPU 3: Put process  5 to run queue
	CPU 2: Put process  7 to run queue
	CPU 1: Put process  1 to run queue
Time slot  14
Time slot  15
Time slot  16
	Loaded a process at input/proc/s1, PID: 8 PRIO: 0
	CPU 3: Dispatched process  8
	CPU 1: Dispatched process  7
	CPU 0: Dispatched process  6
	CPU 2: Dispatched process  3
Time slot  17
Time slot  18
	CPU 0: Put process  6 to run queue
	CPU 0: Dispatched process  2
	CPU 3: Put process  8 to run queue
	CPU 3: Dispatched process  5
	CPU 1: Put process  7 to run queue
	CPU 1: Dispatched process  4
	CPU 2: Put process  3 to run queue
	CPU 2: Dispatched process  1
Time slot  19
	CPU 3: Processed  5 has finished
	CPU 3 stopped
Time slot  20
	CPU 0: Put process  2 to run queue
	CPU 0 stopped
	CPU 2: Processed  1 has finished
	CPU 2 stopped
	CPU 1: Put process  4 to run queue
	CPU 1 stopped
