Time slot   0
ld_routine
	Loaded a process at input/proc/p1s, PID: 1 PRIO: 139
	CPU 0: Dispatched process  1
Time slot   1
	Loaded a process at input/proc/p2s, PID: 2 PRIO: 138
	CPU 0: Put process  1 to run queue
	CPU 0: Dispatched process  1
	CPU 1: Dispatched process  2
Time slot   2
	Loaded a process at input/proc/p3s, PID: 3 PRIO: 136
	CPU 0: Put process  1 to run queue
	CPU 0: Dispatched process  3
	CPU 1: Put process  2 to run queue
	CPU 1: Dispatched process  2
Time slot   3
	Loaded a process at input/proc/p3s, PID: 4 PRIO: 137
	CPU 1: Put process  2 to run queue
	CPU 1: Dispatched process  4
	CPU 0: Put process  3 to run queue
	CPU 0: Dispatched process  3
Time slot   4
	CPU 0: Put process  3 to run queue
	CPU 0: Dispatched process  3
	CPU 1: Put process  4 to run queue
	CPU 1: Dispatched process  4
Time slot   5
	CPU 1: Put process  4 to run queue
	CPU 1: Dispatched process  4
	CPU 0: Put process  3 to run queue
	CPU 0: Dispatched process  3
Time slot   6
	CPU 0: Put process  3 to run queue
	CPU 1: Put process  4 to run queue
	CPU 0: Dispatched process  3
	CPU 1: Dispatched process  4
Time slot   7
	CPU 1: Put process  4 to run queue
	CPU 1: Dispatched process  4
	CPU 0: Put process  3 to run queue
	CPU 0: Dispatched process  3
Time slot   8
	CPU 1: Put process  4 to run queue
	CPU 1: Dispatched process  4
	CPU 0: Put process  3 to run queue
	CPU 0: Dispatched process  3
Time slot   9
	CPU 1: Put process  4 to run queue
	CPU 1: Dispatched process  4
	CPU 0: Put process  3 to run queue
	CPU 0: Dispatched process  3
Time slot  10
	CPU 1: Put process  4 to run queue
	CPU 1: Dispatched process  4
	CPU 0: Put process  3 to run queue
	CPU 0: Dispatched process  3
Time slot  11
	CPU 0: Put process  3 to run queue
	CPU 0: Dispatched process  3
	CPU 1: Put process  4 to run queue
	CPU 1: Dispatched process  4
Time slot  12
	CPU 0: Put process  3 to run queue
	CPU 0: Dispatched process  3
	CPU 1: Put process  4 to run queue
	CPU 1: Dispatched process  4
Time slot  13
	CPU 0: Processed  3 has finished
	CPU 0: Dispatched process  2
	CPU 1: Put process  4 to run queue
	CPU 1: Dispatched process  4
Time slot  14
	CPU 1: Processed  4 has finished
	CPU 0: Put process  2 to run queue
	CPU 0: Dispatched process  2
	CPU 1: Dispatched process  1
Time slot  15
	CPU 1: Put process  1 to run queue
	CPU 1: Dispatched process  1
	CPU 0: Put process  2 to run queue
	CPU 0: Dispatched process  2
Time slot  16
	CPU 1: Put process  1 to run queue
	CPU 1: Dispatched process  1
	CPU 0: Put process  2 to run queue
	CPU 0: Dispatched process  2
Time slot  17
	CPU 0: Put process  2 to run queue
	CPU 0: Dispatched process  2
	CPU 1: Put process  1 to run queue
	CPU 1: Dispatched process  1
Time slot  18
	CPU 1: Put process  1 to run queue
	CPU 1: Dispatched process  1
	CPU 0: Put process  2 to run queue
	CPU 0: Dispatched process  2
Time slot  19
	CPU 1: Put process  1 to run queue
	CPU 1: Dispatched process  1
	CPU 0: Put process  2 to run queue
	CPU 0: Dispatched process  2
Time slot  20
	CPU 1: Put process  1 to run queue
	CPU 1: Dispatched process  1
	CPU 0: Put process  2 to run queue
	CPU 0: Dispatched process  2
Time slot  21
	CPU 1: Put process  1 to run queue
	CPU 1: Dispatched process  1
	CPU 0: Put process  2 to run queue
	CPU 0: Dispatched process  2
Time slot  22
	CPU 1: Processed  1 has finished
	CPU 1 stopped
	CPU 0: Put process  2 to run queue
	CPU 0: Dispatched process  2
Time slot  23
	CPU 0: Processed  2 has finished
	CPU 0 stopped
